<?xml version="1.0" ?>
<!-- =================================================================================== -->
<!-- |    This document was autogenerated by xacro from pera.xacro                     | -->
<!-- |    EDITING THIS FILE BY HAND IS NOT RECOMMENDED                                 | -->
<!-- =================================================================================== -->
<robot name="pera" xmlns:xacro="http://ros.org/wiki/xacro">
  <!-- Included URDF Files -->
  <!--
   <author>Kris van Tienhoven</author>
   <license>BSD</license>
   <review status="unreviewed" notes=""/>
-->
  <!-- this files contains the definitions for all colors and textures for rviz -->
  <material name="Blue">
    <color rgba="0.0 0.0 0.8 1.0"/>
  </material>
  <material name="Green">
    <color rgba="0.0 0.8 0.0 1.0"/>
  </material>
  <material name="Grey">
    <color rgba="0.7 0.7 0.7 1.0"/>
  </material>
  <material name="Grey2">
    <color rgba="0.9 0.9 0.9 1.0"/>
  </material>
  <material name="Red">
    <color rgba="0.8 0.0 0.0 1.0"/>
  </material>
  <material name="White">
    <color rgba="1.0 1.0 1.0 1.0"/>
  </material>
  <material name="Black">
    <color rgba="0.1 0.1 0.1 1.0"/>
  </material>
  <material name="LightGrey">
    <color rgba="0.6 0.6 0.6 1.0"/>
  </material>
  <material name="amigo_description/bottomcovers">
    <texture filename="package://robot2_description/meshes/media/materials/textures/bottomcovers/finalreduced.jpg"/>
  </material>
  <material name="amigo_description/white">
    <texture filename="package://robot2_description/meshes/media/materials/textures/white/white.jpg"/>
  </material>
  <material name="amigo_description/logo">
    <texture filename="package://robot2_description/meshes/media/materials/textures/logo/tue.jpg"/>
  </material>
  <material name="amigo_description/aluminium">
    <texture filename="package://robot2_description/meshes/media/materials/textures/aluminium/aluminium_0001_c.jpg"/>
  </material>
  <material name="amigo_description/orange">
    <texture filename="package://robot2_description/meshes/media/materials/textures/orange/orange.jpg"/>
  </material>
  <!-- *************** LINK Definitions *****************-->
  <!--   <author>Kris van Tienhoven</author>
   <license>BSD</license>
   <review status="unreviewed" notes=""/> -->
  <!--use this type of link for standard shapes (bos, cylinder, sphere) with standard color -->
  <!-- use this type of link if you want the standard shapes with a texture -->
  <!--use this type of link for shapes that need to be collision free and thereby also invisible -->
  <!--use this type of link if you want to load a mesh with a standard color -->
  <!-- use this type of link if you want to load a mesh with a texture -->
  <!-- use this type of link if you want a mesh with texture and a different bouding box (then the box around the mesh itself) -->
  <!-- *************** JOINT Definition *****************-->
  <!--    <xacro:include filename="$(find pera_description)/urdf/arms/arm.transmission.xacro" />-->
  <!--
  <author>Rob Janssen, Kris van Tienhoven</author>
  <license>BSD</license>
  <review status="unreviewed" notes=""/>
-->
  <!--Start of the macro
@param whichside is "left"  or "right"
@param sidesign is -1 or +1
@param rollsign is - or +

The reason sidesign is -1 or +1 and not just - or + aswell is because 
it has to be reversable and xml cannot multiply - or + but can multiply
 -1 and +1-->
  <!-- ros_control plugin -->
  <gazebo>
    <!--plugin filename="libgazebo_ros_controller_manager.so" name="gazebo_ros_controller_manager">
      <alwaysOn>true</alwaysOn>
      <updateRate>1000.0</updateRate>
    </plugin-->

   <plugin name="gazebo_ros_control" filename="libgazebo_ros_control.so">
      <robotNamespace>/PERA</robotNamespace>
      <robotSimType>gazebo_ros_control/DefaultRobotHWSim</robotSimType>
   </plugin>
  </gazebo>
  
  <!-- Used for fixing robot to Gazebo 'base_link' -->
  <link name="world"/>
  <!-- the arm -->
  <!--the end of the clavicle, yaw rotation-->
  <link name="shoulder_mount">
    <inertial>
      <origin rpy="0 0 0" xyz="0.0 0.0 0.0"/>
      <mass value="0.15"/>
      <inertia ixx="0.01" ixy="0" ixz="0" iyy="0.01" iyz="0" izz="0.01"/>
    </inertial>
    <visual>
      <origin rpy="0 0 0 " xyz="0.0 0.0 0.0"/>
      <geometry>
        <cylinder length="0.11" radius="0.05"/>
      </geometry>
      <material name="Grey2">
     </material>
    </visual>
    <collision>
      <origin rpy="0 0 0 " xyz="0.0 0.0 0.0"/>
      <geometry>
        <cylinder length="0.11" radius="0.05"/>
      </geometry>
    </collision>
  </link>
  <gazebo reference="shoulder_mount">
    <material>Grey2</material>
    <turnGravityOff>false</turnGravityOff>
  </gazebo>
  <!--the cylinder on the end of the clavicle, pitch rotation-->
  <link name="shoulder_link1">
    <inertial>
      <origin rpy="0 0 0" xyz="0.0 0.0 0.0"/>
      <mass value="0.25"/>
      <inertia ixx="6.0" ixy="0" ixz="0" iyy="0.01" iyz="0" izz="0.01"/>
    </inertial>
    <visual>
      <origin rpy="0 0 0 " xyz="0.0 0.0 0.0525"/>
      <geometry>
        <cylinder length="0.015" radius="0.045"/>
      </geometry>
      <material name="Black">
     </material>
    </visual>
    <collision>
      <origin rpy="0 0 0 " xyz="0.0 0.0 0.0525"/>
      <geometry>
        <cylinder length="0.015" radius="0.045"/>
      </geometry>
    </collision>
  </link>
  <gazebo reference="shoulder_link1">
    <material>Black</material>
    <turnGravityOff>false</turnGravityOff>
  </gazebo>
  <!--the box that connects the clavicle to the upper arm, roll rotation-->
  <link name="shoulder_link2">
    <inertial>
      <origin rpy="0 0 0" xyz="0.0 0.0 0.0"/>
      <mass value="0.15"/>
      <inertia ixx="0.01" ixy="0" ixz="0" iyy="4.04" iyz="0" izz="0.001"/>
    </inertial>
    <visual>
      <origin rpy="0 0 0" xyz="0.0 -0.06 -0.05"/>
      <geometry>
        <box size="0.035 0.01 0.1"/>
      </geometry>
      <material name="Black">
     </material>
    </visual>
    <collision>
      <origin rpy="0 0 0" xyz="0.0 -0.06 -0.05"/>
      <geometry>
        <box size="0.035 0.01 0.1"/>
      </geometry>
    </collision>
  </link>
  <gazebo reference="shoulder_link2">
    <material>Black</material>
    <turnGravityOff>false</turnGravityOff>
  </gazebo>
  <!--the upper arm-->
  <link name="upper_arm">
    <inertial>
      <origin rpy="0 0 0" xyz="0.0 -0.2 0.0"/>
      <mass value="2.95"/>
      <inertia ixx="0.027" ixy="0" ixz="0" iyy="0.45993" iyz="0" izz="0.004"/>
    </inertial>
    <visual>
      <origin rpy="0 0 3.1415" xyz="-0.00959 -0.19131 -0.00001"/>
      <geometry>
        <mesh filename="package://robot2_description/meshes/media/meshes/upperarmtextured.dae" scale="0.0004 0.0004 0.0004"/>
      </geometry>
      <material name="amigo_description/white"/>
    </visual>
    <collision>
      <origin rpy="0 0 3.1415" xyz="-0.00959 -0.19131 -0.00001"/>
      <geometry>
        <mesh filename="package://robot2_description/meshes/media/meshes/upperarmtextured.dae" scale="0.0004 0.0004 0.0004"/>
      </geometry>
    </collision>
  </link>
  <gazebo reference="upper_arm">
    <material>amigo_description/white</material>
    <turnGravityOff>false</turnGravityOff>
  </gazebo>
  <!--the elbow
note: not visible, see arm_extra_visuals for the elbow visuals -->
  <link name="elbow_link4">
    <inertial>
      <origin rpy="0 0 0" xyz="0.0 0.0 0.0"/>
      <mass value="0.1"/>
      <inertia ixx="0.001" ixy="0" ixz="0" iyy="0.6" iyz="0" izz="0.001"/>
    </inertial>
    <visual>
      <origin rpy="0 0 0" xyz="0.0 0.0 0.0"/>
      <geometry>
        <cylinder length="0.0" radius="0.0"/>
      </geometry>
      <material name="Grey">
     </material>
    </visual>
    <collision>
      <origin rpy="0 0 0" xyz="0.0 0.0 0.0"/>
      <geometry>
        <cylinder length="0.0" radius="0.0"/>
      </geometry>
    </collision>
  </link>
  <gazebo reference="elbow_link4">
    <material>Grey</material>
    <turnGravityOff>false</turnGravityOff>
  </gazebo>
  <!--the forearm-->
  <link name="fore_arm">
    <inertial>
      <origin rpy="0.0 0 0" xyz="0.0 -0.14 0.0"/>
      <mass value="0.85"/>
      <inertia ixx="0.001" ixy="0" ixz="0" iyy="0.5" iyz="0" izz="0.001"/>
    </inertial>
    <visual>
      <origin rpy="0 -1.5708 0" xyz="0.00425 -0.14868 0.00547"/>
      <geometry>
        <mesh filename="package://robot2_description/meshes/media/meshes/forearmtextured.dae" scale="0.0004 0.0004 0.0004"/>
      </geometry>
      <material name="amigo_description/white"/>
    </visual>
    <collision>
      <origin rpy="0 -1.5708 0" xyz="0.00425 -0.14868 0.00547"/>
      <geometry>
        <mesh filename="package://robot2_description/meshes/media/meshes/forearmtextured.dae" scale="0.0004 0.0004 0.0004"/>
      </geometry>
    </collision>
  </link>
  <gazebo reference="fore_arm">
    <material>amigo_description/white</material>
    <turnGravityOff>false</turnGravityOff>
  </gazebo>
  <!--the wrist
note: not visible, see arm_extra_visuals for the wrist visuals -->
  <link name="wrist_link6">
    <inertial>
      <origin rpy="0 0 0" xyz="0.0 0.0 0.0"/>
      <mass value="0.01"/>
      <inertia ixx="0.001" ixy="0" ixz="0" iyy="0.03322" iyz="0" izz="0.001"/>
    </inertial>
    <visual>
      <origin rpy="1.5708 0 0" xyz="0.0 0.0 0.0"/>
      <geometry>
        <cylinder length="0.0" radius="0.0"/>
      </geometry>
      <material name="Black">
     </material>
    </visual>
    <collision>
      <origin rpy="1.5708 0 0" xyz="0.0 0.0 0.0"/>
      <geometry>
        <cylinder length="0.0" radius="0.0"/>
      </geometry>
    </collision>
  </link>
  <gazebo reference="wrist_link6">
    <material>Black</material>
    <turnGravityOff>false</turnGravityOff>
  </gazebo>
  <!--the hand -->
  <link name="hand">
    <inertial>
      <origin rpy="0 0 0" xyz="0.048 0.0 0.0"/>
      <mass value="0.2"/>
      <inertia ixx="0.01" ixy="0" ixz="0" iyy="0.01" iyz="0" izz="0.0622"/>
    </inertial>
    <visual>
      <origin rpy="0 0 0" xyz="0.048 0.0 0.0"/>
      <geometry>
        <box size="0.080 0.085 0.038"/>
      </geometry>
      <material name="Grey">
     </material>
    </visual>
    <collision>
      <origin rpy="0 0 0" xyz="0.048 0.0 0.0"/>
      <geometry>
        <box size="0.080 0.085 0.038"/>
      </geometry>
    </collision>
  </link>
  <gazebo reference="hand">
    <material>Grey</material>
    <turnGravityOff>false</turnGravityOff>
  </gazebo>
  <!--the right finger  hier de link naar de gripper van maken? -->
  <link name="gripper">
    <inertial>
      <origin rpy="0 0 0" xyz="0.0 0.0 -0.03"/>
      <mass value="0.01"/>
      <inertia ixx="0.01" ixy="0" ixz="0" iyy="0.01" iyz="0" izz="0.01"/>
    </inertial>
    <visual>
      <origin rpy="0 0 0" xyz="0.0 0.0 -0.03"/>
      <geometry>
        <box size="0.018 0.018 0.06"/>
      </geometry>
      <material name="White">
     </material>
    </visual>
    <collision>
      <origin rpy="0 0 0" xyz="0.0 0.0 -0.03"/>
      <geometry>
        <box size="0.018 0.018 0.06"/>
      </geometry>
    </collision>
  </link>
  <gazebo reference="gripper">
    <material>White</material>
    <turnGravityOff>false</turnGravityOff>
  </gazebo>
  <gazebo reference="gripper">
    <mu1 value="100.0"/>
    <mu2 value="100.0"/>
  </gazebo>
  <!--the joints start here-->
  <joint name="shoulder_mount_joint" type="fixed">
    <parent link="world"/>
    <child link="shoulder_mount"/>
    <origin rpy="0 -1.57 0" xyz="0 0 1.0"/>
    <!--    <origin xyz="0.05 ${sidesign*0.22} 0.0" rpy="0 0 0.0"/> -->
  </joint>
  <joint name="arm_joint1" type="revolute">
    <parent link="shoulder_mount"/>
    <child link="shoulder_link1"/>
    <origin rpy="-1.5708 -1.5708 0" xyz="0 0 0"/>
    <axis xyz="+1 0 0"/>
    <dynamics damping="4.0" friction="4.87"/>
    <limit effort="13.4" lower="-1.57" upper="0.0" velocity="1.0"/>
  </joint>
  <joint name="shoulder_pitch_joint" type="revolute">
    <parent link="shoulder_link1"/>
    <child link="shoulder_link2"/>
    <origin rpy="-1.5708  0 0" xyz="0.0 0.0 0.0"/>
    <axis xyz="0 -1 0"/>
    <dynamics damping="4.0" friction="6.06"/>
    <limit effort="13.4" lower="-1.57" upper="1.57" velocity="1.0"/>
  </joint>
  <joint name="shoulder_roll_joint" type="revolute">
    <parent link="shoulder_link2"/>
    <child link="upper_arm"/>
    <origin rpy="1.5708 0 0.0" xyz="0.0 0.0 0.0"/>
    <axis xyz="0 1.0 0"/>
    <dynamics damping="3.8" friction="2.216"/>
    <limit effort="9.8" lower="-1.57" upper="1.57" velocity="1.0"/>
  </joint>
  <joint name="arm_joint2" type="revolute">
    <parent link="upper_arm"/>
    <child link="elbow_link4"/>
    <origin rpy="-1.5708 0 0" xyz="0.01 -0.32 0.0"/>
    <axis xyz="0 -1 0"/>
    <dynamics damping="3" friction="1.18"/>
    <limit effort="4.5" lower="0.0" upper="2.23" velocity="1.0"/>
  </joint>
  <joint name="arm_joint3" type="revolute">
    <parent link="elbow_link4"/>
    <child link="fore_arm"/>
    <origin rpy="1.5708 0 0" xyz="0.0 0.0 0.0"/>
    <axis xyz="0 1.0 0"/>
    <dynamics damping="3.5" friction="1.35"/>
    <limit effort="4.5" lower="-1.83" upper="1.83" velocity="1.0"/>
  </joint>
  <joint name="wrist_pitch_joint" type="revolute">
    <parent link="fore_arm"/>
    <child link="wrist_link6"/>
    <origin rpy="-1.5708 0 -1.5708" xyz="0.01 -0.28 0.0"/>
    <axis xyz="0 -1 0"/>
    <dynamics damping="0.35" friction="0.63"/>
    <limit effort="1" lower="-0.95" upper="0.95" velocity="1.0"/>
  </joint>
  <joint name="wrist_yaw_joint" type="revolute">
    <parent link="wrist_link6"/>
    <child link="hand"/>
    <origin rpy="0 0 0" xyz="0.0 0.0 0.0"/>
    <axis xyz="0 0 1.01"/>
    <dynamics damping="0.3" friction="0.68"/>
    <limit effort="1" lower="-0.61" upper="0.61" velocity="1.0"/>
  </joint>
  <!-- de gripper joint van maken -->
  <joint name="gripper_joint" type="revolute">
    <parent link="hand"/>
    <child link="gripper"/>
    <origin rpy="0 -1.57 0" xyz=" 0.075 0.02 0"/>
    <axis xyz="1 0 0"/>
    <dynamics damping="0.5" friction="1.0"/>
    <limit effort="3" lower="0.2" upper="1" velocity="1.0"/>
  </joint>
  <!-- Camera -->
  <joint name="camera_joint" type="fixed">
    <origin rpy="0 0 3.14159" xyz="1 -0.2 0.2"/>
    <parent link="world"/>
    <child link="camera_link"/>
  </joint>
  <link name="camera_link">
    <collision>
      <origin rpy="0 0 0" xyz="0 0 0"/>
      <geometry>
        <box size="0.1 0.1 0.1"/>
      </geometry>
    </collision>
    <visual>
      <origin rpy="0 0 0" xyz="0 0 0"/>
      <geometry>
        <box size="0.02 0.02 0.02"/>
      </geometry>
      <material name="Red"/>
    </visual>
    <inertial>
      <mass value="1e-5"/>
      <origin rpy="0 0 0" xyz="0 0 0"/>
      <inertia ixx="1e-6" ixy="0" ixz="0" iyy="1e-6" iyz="0" izz="1e-6"/>
    </inertial>
  </link>
  
  
  <xacro:transmission joint_name="arm_joint1">
		</xacro:transmission>
	<xacro:transmission joint_name="arm_joint2">
		</xacro:transmission>
 	<xacro:transmission joint_name="arm_joint3">
		</xacro:transmission>
</robot>

